Workbook

Sheet Tamu 
A1: UNDANGAN WEBSITE
A2: Nama Tamu | B2: Bagian | C2: Link Undangan | D2: Nomor WA | E2: Kirim WA | F2: Terkirim?
A3: Adwin Nugroho Bachtiar | B3: Subbagian Tata Usaha | C3: =HYPERLINK(Pengaturan!$B$3&"?to="&SUBSTITUTE(SUBSTITUTE(SUBSTITUTE(TRIM(A3),"%","%25"),"&","%26")," ","%20"),Pengaturan!$B$3&"?to="&SUBSTITUTE(SUBSTITUTE(SUBSTITUTE(TRIM(A3),"%","%25"),"&","%26")," ","%20")) | D3: 081211685320 | E3: 📲 Kirim WA
A4: Ahmad Irhamni | C4: =HYPERLINK(Pengaturan!$B$3&"?to="&SUBSTITUTE(SUBSTITUTE(SUBSTITUTE(TRIM(A4),"%","%25"),"&","%26")," ","%20"),Pengaturan!$B$3&"?to="&SUBSTITUTE(SUBSTITUTE(SUBSTITUTE(TRIM(A4),"%","%25"),"&","%26")," ","%20")) | D4: 081584032175 | E4: 📲 Kirim WA
A5: Annisa Fitria Wardani | C5: =HYPERLINK(Pengaturan!$B$3&"?to="&SUBSTITUTE(SUBSTITUTE(SUBSTITUTE(TRIM(A5),"%","%25"),"&","%26")," ","%20"),Pengaturan!$B$3&"?to="&SUBSTITUTE(SUBSTITUTE(SUBSTITUTE(TRIM(A5),"%","%25"),"&","%26")," ","%20")) | D5: 081237543933 | E5: 📲 Kirim WA
A6: Annisa Nur Asmara | C6: =HYPERLINK(Pengaturan!$B$3&"?to="&SUBSTITUTE(SUBSTITUTE(SUBSTITUTE(TRIM(A6),"%","%25"),"&","%26")," ","%20"),Pengaturan!$B$3&"?to="&SUBSTITUTE(SUBSTITUTE(SUBSTITUTE(TRIM(A6),"%","%25"),"&","%26")," ","%20")) | D6: 081224505608 | E6: 📲 Kirim WA
A7: Ardi Dwi Rahmat | C7: =HYPERLINK(Pengaturan!$B$3&"?to="&SUBSTITUTE(SUBSTITUTE(SUBSTITUTE(TRIM(A7),"%","%25"),"&","%26")," ","%20"),Pengaturan!$B$3&"?to="&SUBSTITUTE(SUBSTITUTE(SUBSTITUTE(TRIM(A7),"%","%25"),"&","%26")," ","%20")) | D7: 089666946946 | E7: 📲 Kirim WA
A8: Daisy Astantia | C8: =HYPERLINK(Pengaturan!$B$3&"?to="&SUBSTITUTE(SUBSTITUTE(SUBSTITUTE(TRIM(A8),"%","%25"),"&","%26")," ","%20"),Pengaturan!$B$3&"?to="&SUBSTITUTE(SUBSTITUTE(SUBSTITUTE(TRIM(A8),"%","%25"),"&","%26")," ","%20")) | D8: 085708570432 | E8: 📲 Kirim WA
A9: Deasy Sherdianty | C9: =HYPERLINK(Pengaturan!$B$3&"?to="&SUBSTITUTE(SUBSTITUTE(SUBSTITUTE(TRIM(A9),"%","%25"),"&","%26")," ","%20"),Pengaturan!$B$3&"?to="&SUBSTITUTE(SUBSTITUTE(SUBSTITUTE(TRIM(A9),"%","%25"),"&","%26")," ","%20")) | D9: 0816893134 | E9: 📲 Kirim WA
A10: Dian Megawati | C10: =HYPERLINK(Pengaturan!$B$3&"?to="&SUBSTITUTE(SUBSTITUTE(SUBSTITUTE(TRIM(A10),"%","%25"),"&","%26")," ","%20"),Pengaturan!$B$3&"?to="&SUBSTITUTE(SUBSTITUTE(SUBSTITUTE(TRIM(A10),"%","%25"),"&","%26")," ","%20")) | D10: 087809111701 | E10: 📲 Kirim WA
A11: Dicki Rinaldi | C11: =HYPERLINK(Pengaturan!$B$3&"?to="&SUBSTITUTE(SUBSTITUTE(SUBSTITUTE(TRIM(A11),"%","%25"),"&","%26")," ","%20"),Pengaturan!$B$3&"?to="&SUBSTITUTE(SUBSTITUTE(SUBSTITUTE(TRIM(A11),"%","%25"),"&","%26")," ","%20")) | D11: 0817617651 | E11: 📲 Kirim WA
A12: Dimas Rizqi Dwiaji | C12: =HYPERLINK(Pengaturan!$B$3&"?to="&SUBSTITUTE(SUBSTITUTE(SUBSTITUTE(TRIM(A12),"%","%25"),"&","%26")," ","%20"),Pengaturan!$B$3&"?to="&SUBSTITUTE(SUBSTITUTE(SUBSTITUTE(TRIM(A12),"%","%25"),"&","%26")," ","%20")) | D12: 085782854355 | E12: 📲 Kirim WA
A13: Fatchurrosy | C13: =HYPERLINK(Pengaturan!$B$3&"?to="&SUBSTITUTE(SUBSTITUTE(SUBSTITUTE(TRIM(A13),"%","%25"),"&","%26")," ","%20"),Pengaturan!$B$3&"?to="&SUBSTITUTE(SUBSTITUTE(SUBSTITUTE(TRIM(A13),"%","%25"),"&","%26")," ","%20")) | D13: 082277215587 | E13: 📲 Kirim WA
A14: Friska Uli Junita Astuty Sianturi | C14: =HYPERLINK(Pengaturan!$B$3&"?to="&SUBSTITUTE(SUBSTITUTE(SUBSTITUTE(TRIM(A14),"%","%25"),"&","%26")," ","%20"),Pengaturan!$B$3&"?to="&SUBSTITUTE(SUBSTITUTE(SUBSTITUTE(TRIM(A14),"%","%25"),"&","%26")," ","%20")) | D14: 081280995706 | E14: 📲 Kirim WA
A15: Hermansyah | C15: =HYPERLINK(Pengaturan!$B$3&"?to="&SUBSTITUTE(SUBSTITUTE(SUBSTITUTE(TRIM(A15),"%","%25"),"&","%26")," ","%20"),Pengaturan!$B$3&"?to="&SUBSTITUTE(SUBSTITUTE(SUBSTITUTE(TRIM(A15),"%","%25"),"&","%26")," ","%20")) | D15: 085315440806 | E15: 📲 Kirim WA
... A21: Wahyudin | C21: =HYPERLINK(Pengaturan!$B$3&"?to="&SUBSTITUTE(SUBSTITUTE(SUBSTITUTE(TRIM(A21),"%","%25"),"&","%26")," ","%20"),Pengaturan!$B$3&"?to="&SUBSTITUTE(SUBSTITUTE(SUBSTITUTE(TRIM(A21),"%","%25"),"&","%26")," ","%20")) | D21: 087880780971 | E21: 📲 Kirim WA
A22: Yuli Suryani | B22: Bagian Pemindahtanganan, Pemusnahan, dan Penghapusan BMN | C22: =HYPERLINK(Pengaturan!$B$3&"?to="&SUBSTITUTE(SUBSTITUTE(SUBSTITUTE(TRIM(A22),"%","%25"),"&","%26")," ","%20"),Pengaturan!$B$3&"?to="&SUBSTITUTE(SUBSTITUTE(SUBSTITUTE(TRIM(A22),"%","%25"),"&","%26")," ","%20")) | D22: 081218828293 | E22: 📲 Kirim WA
A23: Agus Prayoga | C23: =HYPERLINK(Pengaturan!$B$3&"?to="&SUBSTITUTE(SUBSTITUTE(SUBSTITUTE(TRIM(A23),"%","%25"),"&","%26")," ","%20"),Pengaturan!$B$3&"?to="&SUBSTITUTE(SUBSTITUTE(SUBSTITUTE(TRIM(A23),"%","%25"),"&","%26")," ","%20")) | D23: 081385101151 | E23: 📲 Kirim WA
A24: Beny Rudianto | C24: =HYPERLINK(Pengaturan!$B$3&"?to="&SUBSTITUTE(SUBSTITUTE(SUBSTITUTE(TRIM(A24),"%","%25"),"&","%26")," ","%20"),Pengaturan!$B$3&"?to="&SUBSTITUTE(SUBSTITUTE(SUBSTITUTE(TRIM(A24),"%","%25"),"&","%26")," ","%20")) | D24: 089682257774 | E24: 📲 Kirim WA
A25: Carlos Tua March Siburian | C25: =HYPERLINK(Pengaturan!$B$3&"?to="&SUBSTITUTE(SUBSTITUTE(SUBSTITUTE(TRIM(A25),"%","%25"),"&","%26")," ","%20"),Pengaturan!$B$3&"?to="&SUBSTITUTE(SUBSTITUTE(SUBSTITUTE(TRIM(A25),"%","%25"),"&","%26")," ","%20")) | D25: 082170563492 | E25: 📲 Kirim WA
A26: Dawiyah | C26: =HYPERLINK(Pengaturan!$B$3&"?to="&SUBSTITUTE(SUBSTITUTE(SUBSTITUTE(TRIM(A26),"%","%25"),"&","%26")," ","%20"),Pengaturan!$B$3&"?to="&SUBSTITUTE(SUBSTITUTE(SUBSTITUTE(TRIM(A26),"%","%25"),"&","%26")," ","%20")) | D26: 085223264491 | E26: 📲 Kirim WA
A27: Fajar Nugraha | C27: =HYPERLINK(Pengaturan!$B$3&"?to="&SUBSTITUTE(SUBSTITUTE(SUBSTITUTE(TRIM(A27),"%","%25"),"&","%26")," ","%20"),Pengaturan!$B$3&"?to="&SUBSTITUTE(SUBSTITUTE(SUBSTITUTE(TRIM(A27),"%","%25"),"&","%26")," ","%20")) | D27: 082126789713 | E27: 📲 Kirim WA
A28: Hafizh Zaghlul Rizal | C28: =HYPERLINK(Pengaturan!$B$3&"?to="&SUBSTITUTE(SUBSTITUTE(SUBSTITUTE(TRIM(A28),"%","%25"),"&","%26")," ","%20"),Pengaturan!$B$3&"?to="&SUBSTITUTE(SUBSTITUTE(SUBSTITUTE(TRIM(A28),"%","%25"),"&","%26")," ","%20")) | D28: 089505724068 | E28: 📲 Kirim WA
A29: Hendri Febrianto | C29: =HYPERLINK(Pengaturan!$B$3&"?to="&SUBSTITUTE(SUBSTITUTE(SUBSTITUTE(TRIM(A29),"%","%25"),"&","%26")," ","%20"),Pengaturan!$B$3&"?to="&SUBSTITUTE(SUBSTITUTE(SUBSTITUTE(TRIM(A29),"%","%25"),"&","%26")," ","%20")) | D29: 081395863943 | E29: 📲 Kirim WA
A30: Hutamaning Margo Raharjo | C30: =HYPERLINK(Pengaturan!$B$3&"?to="&SUBSTITUTE(SUBSTITUTE(SUBSTITUTE(TRIM(A30),"%","%25"),"&","%26")," ","%20"),Pengaturan!$B$3&"?to="&SUBSTITUTE(SUBSTITUTE(SUBSTITUTE(TRIM(A30),"%","%25"),"&","%26")," ","%20")) | D30: 08123381961 | E30: 📲 Kirim WA
A31: Isabela Reksa Dini | C31: =HYPERLINK(Pengaturan!$B$3&"?to="&SUBSTITUTE(SUBSTITUTE(SUBSTITUTE(TRIM(A31),"%","%25"),"&","%26")," ","%20"),Pengaturan!$B$3&"?to="&SUBSTITUTE(SUBSTITUTE(SUBSTITUTE(TRIM(A31),"%","%25"),"&","%26")," ","%20")) | D31: 085225191119 | E31: 📲 Kirim WA
A32: Lia Yulianti | C32: =HYPERLINK(Pengaturan!$B$3&"?to="&SUBSTITUTE(SUBSTITUTE(SUBSTITUTE(TRIM(A32),"%","%25"),"&","%26")," ","%20"),Pengaturan!$B$3&"?to="&SUBSTITUTE(SUBSTITUTE(SUBSTITUTE(TRIM(A32),"%","%25"),"&","%26")," ","%20")) | D32: 081321120878 | E32: 📲 Kirim WA
A33: Nail Rizqi Afwanadli Purba | C33: =HYPERLINK(Pengaturan!$B$3&"?to="&SUBSTITUTE(SUBSTITUTE(SUBSTITUTE(TRIM(A33),"%","%25"),"&","%26")," ","%20"),Pengaturan!$B$3&"?to="&SUBSTITUTE(SUBSTITUTE(SUBSTITUTE(TRIM(A33),"%","%25"),"&","%26")," ","%20")) | D33: 08567898758 | E33: 📲 Kirim WA
A34: Rayi Setyaningsih | C34: =HYPERLINK(Pengaturan!$B$3&"?to="&SUBSTITUTE(SUBSTITUTE(SUBSTITUTE(TRIM(A34),"%","%25"),"&","%26")," ","%20"),Pengaturan!$B$3&"?to="&SUBSTITUTE(SUBSTITUTE(SUBSTITUTE(TRIM(A34),"%","%25"),"&","%26")," ","%20")) | D34: 08158020738 | E34: 📲 Kirim WA
... A38: Yujiyono | C38: =HYPERLINK(Pengaturan!$B$3&"?to="&SUBSTITUTE(SUBSTITUTE(SUBSTITUTE(TRIM(A38),"%","%25"),"&","%26")," ","%20"),Pengaturan!$B$3&"?to="&SUBSTITUTE(SUBSTITUTE(SUBSTITUTE(TRIM(A38),"%","%25"),"&","%26")," ","%20")) | D38: 087785622219 | E38: 📲 Kirim WA
A39: Gamal Maulian | B39: Bagian Penatausahaan, Penggunaan, dan RKBMN | C39: =HYPERLINK(Pengaturan!$B$3&"?to="&SUBSTITUTE(SUBSTITUTE(SUBSTITUTE(TRIM(A39),"%","%25"),"&","%26")," ","%20"),Pengaturan!$B$3&"?to="&SUBSTITUTE(SUBSTITUTE(SUBSTITUTE(TRIM(A39),"%","%25"),"&","%26")," ","%20")) | D39: 085624939362 | E39: 📲 Kirim WA
A40: Afiifah Eka Prastiyani | C40: =HYPERLINK(Pengaturan!$B$3&"?to="&SUBSTITUTE(SUBSTITUTE(SUBSTITUTE(TRIM(A40),"%","%25"),"&","%26")," ","%20"),Pengaturan!$B$3&"?to="&SUBSTITUTE(SUBSTITUTE(SUBSTITUTE(TRIM(A40),"%","%25"),"&","%26")," ","%20")) | D40: 082137071163 | E40: 📲 Kirim WA
A41: Ahmad Maulana | C41: =HYPERLINK(Pengaturan!$B$3&"?to="&SUBSTITUTE(SUBSTITUTE(SUBSTITUTE(TRIM(A41),"%","%25"),"&","%26")," ","%20"),Pengaturan!$B$3&"?to="&SUBSTITUTE(SUBSTITUTE(SUBSTITUTE(TRIM(A41),"%","%25"),"&","%26")," ","%20")) | D41: 085692422071 | E41: 📲 Kirim WA
A42: Ahmad Zaki | C42: =HYPERLINK(Pengaturan!$B$3&"?to="&SUBSTITUTE(SUBSTITUTE(SUBSTITUTE(TRIM(A42),"%","%25"),"&","%26")," ","%20"),Pengaturan!$B$3&"?to="&SUBSTITUTE(SUBSTITUTE(SUBSTITUTE(TRIM(A42),"%","%25"),"&","%26")," ","%20")) | D42: 081217785737 | E42: 📲 Kirim WA
A43: Amir Husein Sarumpaet | C43: =HYPERLINK(Pengaturan!$B$3&"?to="&SUBSTITUTE(SUBSTITUTE(SUBSTITUTE(TRIM(A43),"%","%25"),"&","%26")," ","%20"),Pengaturan!$B$3&"?to="&SUBSTITUTE(SUBSTITUTE(SUBSTITUTE(TRIM(A43),"%","%25"),"&","%26")," ","%20")) | D43: 082370918686 | E43: 📲 Kirim WA
A44: Dita Solihati | C44: =HYPERLINK(Pengaturan!$B$3&"?to="&SUBSTITUTE(SUBSTITUTE(SUBSTITUTE(TRIM(A44),"%","%25"),"&","%26")," ","%20"),Pengaturan!$B$3&"?to="&SUBSTITUTE(SUBSTITUTE(SUBSTITUTE(TRIM(A44),"%","%25"),"&","%26")," ","%20")) | D44: 0895384198186 | E44: 📲 Kirim WA
A45: Fakhri Jauhari Patria | C45: =HYPERLINK(Pengaturan!$B$3&"?to="&SUBSTITUTE(SUBSTITUTE(SUBSTITUTE(TRIM(A45),"%","%25"),"&","%26")," ","%20"),Pengaturan!$B$3&"?to="&SUBSTITUTE(SUBSTITUTE(SUBSTITUTE(TRIM(A45),"%","%25"),"&","%26")," ","%20")) | D45: 085274060101 | E45: 📲 Kirim WA
A46: Gd Arya Mahendra Putra | C46: =HYPERLINK(Pengaturan!$B$3&"?to="&SUBSTITUTE(SUBSTITUTE(SUBSTITUTE(TRIM(A46),"%","%25"),"&","%26")," ","%20"),Pengaturan!$B$3&"?to="&SUBSTITUTE(SUBSTITUTE(SUBSTITUTE(TRIM(A46),"%","%25"),"&","%26")," ","%20")) | D46: 082125155515 | E46: 📲 Kirim WA
A47: Hilal Hasbiallah | C47: =HYPERLINK(Pengaturan!$B$3&"?to="&SUBSTITUTE(SUBSTITUTE(SUBSTITUTE(TRIM(A47),"%","%25"),"&","%26")," ","%20"),Pengaturan!$B$3&"?to="&SUBSTITUTE(SUBSTITUTE(SUBSTITUTE(TRIM(A47),"%","%25"),"&","%26")," ","%20")) | D47: 081315041686 | E47: 📲 Kirim WA
A48: Monika Widiyana | C48: =HYPERLINK(Pengaturan!$B$3&"?to="&SUBSTITUTE(SUBSTITUTE(SUBSTITUTE(TRIM(A48),"%","%25"),"&","%26")," ","%20"),Pengaturan!$B$3&"?to="&SUBSTITUTE(SUBSTITUTE(SUBSTITUTE(TRIM(A48),"%","%25"),"&","%26")," ","%20")) | D48: 081314291276 | E48: 📲 Kirim WA
...

Sheet Pengaturan
A1: PENGATURAN LINK & PESAN
A2: Pengaturan | B2: Isi (sel kuning boleh diubah) | C2: Keterangan
A3: Alamat website undangan | B3: https://weddingditonike.vercel.app/ | C3: Ganti dengan alamat undangan di Vercel. Semua link di sheet Tamu ikut berubah otomatis.
A4: Template pesan WhatsApp | B4: Dengan hormat, Kepada Yth. Bapak/Ibu/Saudara/i *{NAMA}* Dengan penuh rasa syukur dan sukacita, kami bermaksud melangsungkan pernikahan: *Dito Alfarizi, S.Kom.* & *Nike Sri Maharani, A.Md.M.* 🗓 Minggu, 1 November 2026 🕘 Akad 09.00 WIB | Resepsi 12.00 WIB 📍 Nike Futsal, Kuala Namu, Deli Serdang Undangan lengkap: {LINK} Merupakan suatu kehormatan dan kebahagiaan bagi kami apabila Bapak/Ibu/Saudara/i berkenan hadir dan memberikan doa restu. Terima kasih atas perhatiannya. Kami yang berbahagia, *Dito & Nike* | C4: {NAMA} dan {LINK} otomatis diganti per tamu. Tombol "Kirim WA" di sheet Tamu dibuat dari teks ini, jadi kalau teksnya diubah, tombolnya perlu dibuat ulang.
A8: Catatan: nama tamu diambil dari kolom A sheet Tamu. Spasi diubah jadi %20 dan tanda & jadi %26 supaya link aman.
A10: Assalamualaikum Warahmatullahi Wabarakatuh. Dengan memohon rahmat dan ridho Allah SWT, kami bermaksud menyampaikan kabar bahagia bahwa InsyaAllah kami akan melangsungkan pernikahan. Sehubungan dengan hal tersebut, dengan penuh hormat kami mengundang Bapak/Ibu/Saudara/i untuk berkenan hadir serta memberikan doa restu pada acara pernikahan kami. Informasi lengkap mengenai acara dapat dilihat melalui undangan digital berikut: [Undangan Pernikahan Dito & Nike](https://weddingditonike.vercel.app/?to=Adwin+Nugroho+Bachtiar&utm_source=chatgpt.com) Kehadiran serta doa restu Bapak/Ibu/Saudara/i merupakan suatu kehormatan dan kebahagiaan bagi kami. Atas perhatian dan doa yang diberikan, kami sampaikan terima kasih. Wassalamualaikum Warahmatullahi Wabarakatuh. Hormat kami, **Dito & Nike**

Sheet Nomor WA
A1: NO | B1: NAMA LENGKAP | C1: TELP HP
A2: 1 | B2: A. A. Ayu Teni Pratiwi, S.M. | C2: 087857109771
A3: 2 | B3: Abdjad Ariena Artanti, S.H. | C3: 087835422446
A4: 3 | B4: Aditya Putra, S.H. | C4: 085231404074
A5: 4 | B5: Adwin Nugroho Bachtiar, S.Kom., M.T. | C5: 081211685320
A6: 5 | B6: Afiifah Eka Prastiyani, A.Md.Ak | C6: 082137071163
A7: 6 | B7: Agus Prayoga | C7: 081385101151
A8: 7 | B8: Ahmad Hidayat | C8: 082176161677
A9: 8 | B9: Ahmad Irhamni, S.E., M.A. | C9: 081584032175
A10: 9 | B10: Ahmad Maulana | C10: 085692422071
A11: 10 | B11: Ahmad Yani, S.Pd. | C11: 085238885781
A12: 11 | B12: Ahmad Zaki, S.Kom. | C12: 081217785737
A13: 12 | B13: Aidil Ambya Zula, S.T., M.T. | C13: 082276020877
... A202: 201 | B202: Zulkifli Tjatjo | C202: 082311574770
