Workbook

Sheet Tamu 
A1: UNDANGAN WEBSITE
A2: Nama Tamu | B2: Bagian | C2: Link Undangan | D2: Pesan WhatsApp
A3: Adwin Nugroho Bachtiar | B3: Subbagian Tata Usaha | C3: =HYPERLINK(Pengaturan!$B$3&"?to="&SUBSTITUTE(SUBSTITUTE(SUBSTITUTE(TRIM(A3),"%","%25"),"&","%26")," ","%20"),Pengaturan!$B$3&"?to="&SUBSTITUTE(SUBSTITUTE(SUBSTITUTE(TRIM(A3),"%","%25"),"&","%26")," ","%20")) -> https://weddingditonike.vercel.app/?to=Adwin%20Nugroho%20Bachtiar | D3: =Pengaturan!$B$4&CHAR(10)&CHAR(10)&"Kepada Yth."&CHAR(10)&"Bapak/Ibu/Saudara/i"&CHAR(10)&"*"&TRIM(A3)&"*"&CHAR(10)&CHAR(10)&Pengaturan!$B$5&CHAR(10)&Pengaturan!$B$3&"?to="&SUBSTITUTE(SUBSTITUTE(SUBSTITUTE(TRIM(A3),"%","%25"),"&","%26")," ","%20")&CHAR(10)&CHAR(10)&Pengaturan!$B$6 -> Dengan hormat, Kepada Yth. Bapak/Ibu/Saudara/i *Adwin Nugroho Bachtiar* Tanpa mengurangi rasa hormat, perkenankan kami mengundang Bapak/Ibu/Saudara/i untuk menghadiri acara pernikahan kami. Berikut link undangan untuk info lengkap acara: https://weddingditonike.vercel.app/?to=Adwin%20Nugroho%20Bachtiar Merupakan suatu kebahagiaan bagi kami apabila Bapak/Ibu/Saudara/i berkenan hadir dan memberikan doa restu. Terima kasih. Kami yang berbahagia, Dito & Nike
A4: Ahmad Irhamni | C4: =HYPERLINK(Pengaturan!$B$3&"?to="&SUBSTITUTE(SUBSTITUTE(SUBSTITUTE(TRIM(A4),"%","%25"),"&","%26")," ","%20"),Pengaturan!$B$3&"?to="&SUBSTITUTE(SUBSTITUTE(SUBSTITUTE(TRIM(A4),"%","%25"),"&","%26")," ","%20")) -> https://weddingditonike.vercel.app/?to=Ahmad%20Irhamni | D4: =Pengaturan!$B$4&CHAR(10)&CHAR(10)&"Kepada Yth."&CHAR(10)&"Bapak/Ibu/Saudara/i"&CHAR(10)&"*"&TRIM(A4)&"*"&CHAR(10)&CHAR(10)&Pengaturan!$B$5&CHAR(10)&Pengaturan!$B$3&"?to="&SUBSTITUTE(SUBSTITUTE(SUBSTITUTE(TRIM(A4),"%","%25"),"&","%26")," ","%20")&CHAR(10)&CHAR(10)&Pengaturan!$B$6 -> Dengan hormat, Kepada Yth. Bapak/Ibu/Saudara/i *Ahmad Irhamni* Tanpa mengurangi rasa hormat, perkenankan kami mengundang Bapak/Ibu/Saudara/i untuk menghadiri acara pernikahan kami. Berikut link undangan untuk info lengkap acara: https://weddingditonike.vercel.app/?to=Ahmad%20Irhamni Merupakan suatu kebahagiaan bagi kami apabila Bapak/Ibu/Saudara/i berkenan hadir dan memberikan doa restu. Terima kasih. Kami yang berbahagia, Dito & Nike
A5: Annisa Fitria Wardani | C5: =HYPERLINK(Pengaturan!$B$3&"?to="&SUBSTITUTE(SUBSTITUTE(SUBSTITUTE(TRIM(A5),"%","%25"),"&","%26")," ","%20"),Pengaturan!$B$3&"?to="&SUBSTITUTE(SUBSTITUTE(SUBSTITUTE(TRIM(A5),"%","%25"),"&","%26")," ","%20")) -> https://weddingditonike.vercel.app/?to=Annisa%20Fitria%20Wardani | D5: =Pengaturan!$B$4&CHAR(10)&CHAR(10)&"Kepada Yth."&CHAR(10)&"Bapak/Ibu/Saudara/i"&CHAR(10)&"*"&TRIM(A5)&"*"&CHAR(10)&CHAR(10)&Pengaturan!$B$5&CHAR(10)&Pengaturan!$B$3&"?to="&SUBSTITUTE(SUBSTITUTE(SUBSTITUTE(TRIM(A5),"%","%25"),"&","%26")," ","%20")&CHAR(10)&CHAR(10)&Pengaturan!$B$6 -> Dengan hormat, Kepada Yth. Bapak/Ibu/Saudara/i *Annisa Fitria Wardani* Tanpa mengurangi rasa hormat, perkenankan kami mengundang Bapak/Ibu/Saudara/i untuk menghadiri acara pernikahan kami. Berikut link undangan untuk info lengkap acara: https://weddingditonike.vercel.app/?to=Annisa%20Fitria%20Wardani Merupakan suatu kebahagiaan bagi kami apabila Bapak/Ibu/Saudara/i berkenan hadir dan memberikan doa restu. Terima kasih. Kami yang berbahagia, Dito & Nike
A6: Annisa Nur Asmara | C6: =HYPERLINK(Pengaturan!$B$3&"?to="&SUBSTITUTE(SUBSTITUTE(SUBSTITUTE(TRIM(A6),"%","%25"),"&","%26")," ","%20"),Pengaturan!$B$3&"?to="&SUBSTITUTE(SUBSTITUTE(SUBSTITUTE(TRIM(A6),"%","%25"),"&","%26")," ","%20")) -> https://weddingditonike.vercel.app/?to=Annisa%20Nur%20Asmara | D6: =Pengaturan!$B$4&CHAR(10)&CHAR(10)&"Kepada Yth."&CHAR(10)&"Bapak/Ibu/Saudara/i"&CHAR(10)&"*"&TRIM(A6)&"*"&CHAR(10)&CHAR(10)&Pengaturan!$B$5&CHAR(10)&Pengaturan!$B$3&"?to="&SUBSTITUTE(SUBSTITUTE(SUBSTITUTE(TRIM(A6),"%","%25"),"&","%26")," ","%20")&CHAR(10)&CHAR(10)&Pengaturan!$B$6 -> Dengan hormat, Kepada Yth. Bapak/Ibu/Saudara/i *Annisa Nur Asmara* Tanpa mengurangi rasa hormat, perkenankan kami mengundang Bapak/Ibu/Saudara/i untuk menghadiri acara pernikahan kami. Berikut link undangan untuk info lengkap acara: https://weddingditonike.vercel.app/?to=Annisa%20Nur%20Asmara Merupakan suatu kebahagiaan bagi kami apabila Bapak/Ibu/Saudara/i berkenan hadir dan memberikan doa restu. Terima kasih. Kami yang berbahagia, Dito & Nike
A7: Ardi Dwi Rahmat | C7: =HYPERLINK(Pengaturan!$B$3&"?to="&SUBSTITUTE(SUBSTITUTE(SUBSTITUTE(TRIM(A7),"%","%25"),"&","%26")," ","%20"),Pengaturan!$B$3&"?to="&SUBSTITUTE(SUBSTITUTE(SUBSTITUTE(TRIM(A7),"%","%25"),"&","%26")," ","%20")) -> https://weddingditonike.vercel.app/?to=Ardi%20Dwi%20Rahmat | D7: =Pengaturan!$B$4&CHAR(10)&CHAR(10)&"Kepada Yth."&CHAR(10)&"Bapak/Ibu/Saudara/i"&CHAR(10)&"*"&TRIM(A7)&"*"&CHAR(10)&CHAR(10)&Pengaturan!$B$5&CHAR(10)&Pengaturan!$B$3&"?to="&SUBSTITUTE(SUBSTITUTE(SUBSTITUTE(TRIM(A7),"%","%25"),"&","%26")," ","%20")&CHAR(10)&CHAR(10)&Pengaturan!$B$6 -> Dengan hormat, Kepada Yth. Bapak/Ibu/Saudara/i *Ardi Dwi Rahmat* Tanpa mengurangi rasa hormat, perkenankan kami mengundang Bapak/Ibu/Saudara/i untuk menghadiri acara pernikahan kami. Berikut link undangan untuk info lengkap acara: https://weddingditonike.vercel.app/?to=Ardi%20Dwi%20Rahmat Merupakan suatu kebahagiaan bagi kami apabila Bapak/Ibu/Saudara/i berkenan hadir dan memberikan doa restu. Terima kasih. Kami yang berbahagia, Dito & Nike
A8: Daisy Astantia | C8: =HYPERLINK(Pengaturan!$B$3&"?to="&SUBSTITUTE(SUBSTITUTE(SUBSTITUTE(TRIM(A8),"%","%25"),"&","%26")," ","%20"),Pengaturan!$B$3&"?to="&SUBSTITUTE(SUBSTITUTE(SUBSTITUTE(TRIM(A8),"%","%25"),"&","%26")," ","%20")) -> https://weddingditonike.vercel.app/?to=Daisy%20Astantia | D8: =Pengaturan!$B$4&CHAR(10)&CHAR(10)&"Kepada Yth."&CHAR(10)&"Bapak/Ibu/Saudara/i"&CHAR(10)&"*"&TRIM(A8)&"*"&CHAR(10)&CHAR(10)&Pengaturan!$B$5&CHAR(10)&Pengaturan!$B$3&"?to="&SUBSTITUTE(SUBSTITUTE(SUBSTITUTE(TRIM(A8),"%","%25"),"&","%26")," ","%20")&CHAR(10)&CHAR(10)&Pengaturan!$B$6 -> Dengan hormat, Kepada Yth. Bapak/Ibu/Saudara/i *Daisy Astantia* Tanpa mengurangi rasa hormat, perkenankan kami mengundang Bapak/Ibu/Saudara/i untuk menghadiri acara pernikahan kami. Berikut link undangan untuk info lengkap acara: https://weddingditonike.vercel.app/?to=Daisy%20Astantia Merupakan suatu kebahagiaan bagi kami apabila Bapak/Ibu/Saudara/i berkenan hadir dan memberikan doa restu. Terima kasih. Kami yang berbahagia, Dito & Nike
A9: Deasy Sherdianty | C9: =HYPERLINK(Pengaturan!$B$3&"?to="&SUBSTITUTE(SUBSTITUTE(SUBSTITUTE(TRIM(A9),"%","%25"),"&","%26")," ","%20"),Pengaturan!$B$3&"?to="&SUBSTITUTE(SUBSTITUTE(SUBSTITUTE(TRIM(A9),"%","%25"),"&","%26")," ","%20")) -> https://weddingditonike.vercel.app/?to=Deasy%20Sherdianty | D9: =Pengaturan!$B$4&CHAR(10)&CHAR(10)&"Kepada Yth."&CHAR(10)&"Bapak/Ibu/Saudara/i"&CHAR(10)&"*"&TRIM(A9)&"*"&CHAR(10)&CHAR(10)&Pengaturan!$B$5&CHAR(10)&Pengaturan!$B$3&"?to="&SUBSTITUTE(SUBSTITUTE(SUBSTITUTE(TRIM(A9),"%","%25"),"&","%26")," ","%20")&CHAR(10)&CHAR(10)&Pengaturan!$B$6 -> Dengan hormat, Kepada Yth. Bapak/Ibu/Saudara/i *Deasy Sherdianty* Tanpa mengurangi rasa hormat, perkenankan kami mengundang Bapak/Ibu/Saudara/i untuk menghadiri acara pernikahan kami. Berikut link undangan untuk info lengkap acara: https://weddingditonike.vercel.app/?to=Deasy%20Sherdianty Merupakan suatu kebahagiaan bagi kami apabila Bapak/Ibu/Saudara/i berkenan hadir dan memberikan doa restu. Terima kasih. Kami yang berbahagia, Dito & Nike
A10: Dian Megawati | C10: =HYPERLINK(Pengaturan!$B$3&"?to="&SUBSTITUTE(SUBSTITUTE(SUBSTITUTE(TRIM(A10),"%","%25"),"&","%26")," ","%20"),Pengaturan!$B$3&"?to="&SUBSTITUTE(SUBSTITUTE(SUBSTITUTE(TRIM(A10),"%","%25"),"&","%26")," ","%20")) -> https://weddingditonike.vercel.app/?to=Dian%20Megawati | D10: =Pengaturan!$B$4&CHAR(10)&CHAR(10)&"Kepada Yth."&CHAR(10)&"Bapak/Ibu/Saudara/i"&CHAR(10)&"*"&TRIM(A10)&"*"&CHAR(10)&CHAR(10)&Pengaturan!$B$5&CHAR(10)&Pengaturan!$B$3&"?to="&SUBSTITUTE(SUBSTITUTE(SUBSTITUTE(TRIM(A10),"%","%25"),"&","%26")," ","%20")&CHAR(10)&CHAR(10)&Pengaturan!$B$6 -> Dengan hormat, Kepada Yth. Bapak/Ibu/Saudara/i *Dian Megawati* Tanpa mengurangi rasa hormat, perkenankan kami mengundang Bapak/Ibu/Saudara/i untuk menghadiri acara pernikahan kami. Berikut link undangan untuk info lengkap acara: https://weddingditonike.vercel.app/?to=Dian%20Megawati Merupakan suatu kebahagiaan bagi kami apabila Bapak/Ibu/Saudara/i berkenan hadir dan memberikan doa restu. Terima kasih. Kami yang berbahagia, Dito & Nike
A11: Dicki Rinaldi | C11: =HYPERLINK(Pengaturan!$B$3&"?to="&SUBSTITUTE(SUBSTITUTE(SUBSTITUTE(TRIM(A11),"%","%25"),"&","%26")," ","%20"),Pengaturan!$B$3&"?to="&SUBSTITUTE(SUBSTITUTE(SUBSTITUTE(TRIM(A11),"%","%25"),"&","%26")," ","%20")) -> https://weddingditonike.vercel.app/?to=Dicki%20Rinaldi | D11: =Pengaturan!$B$4&CHAR(10)&CHAR(10)&"Kepada Yth."&CHAR(10)&"Bapak/Ibu/Saudara/i"&CHAR(10)&"*"&TRIM(A11)&"*"&CHAR(10)&CHAR(10)&Pengaturan!$B$5&CHAR(10)&Pengaturan!$B$3&"?to="&SUBSTITUTE(SUBSTITUTE(SUBSTITUTE(TRIM(A11),"%","%25"),"&","%26")," ","%20")&CHAR(10)&CHAR(10)&Pengaturan!$B$6 -> Dengan hormat, Kepada Yth. Bapak/Ibu/Saudara/i *Dicki Rinaldi* Tanpa mengurangi rasa hormat, perkenankan kami mengundang Bapak/Ibu/Saudara/i untuk menghadiri acara pernikahan kami. Berikut link undangan untuk info lengkap acara: https://weddingditonike.vercel.app/?to=Dicki%20Rinaldi Merupakan suatu kebahagiaan bagi kami apabila Bapak/Ibu/Saudara/i berkenan hadir dan memberikan doa restu. Terima kasih. Kami yang berbahagia, Dito & Nike
A12: Dimas Rizqi Dwiaji | C12: =HYPERLINK(Pengaturan!$B$3&"?to="&SUBSTITUTE(SUBSTITUTE(SUBSTITUTE(TRIM(A12),"%","%25"),"&","%26")," ","%20"),Pengaturan!$B$3&"?to="&SUBSTITUTE(SUBSTITUTE(SUBSTITUTE(TRIM(A12),"%","%25"),"&","%26")," ","%20")) -> https://weddingditonike.vercel.app/?to=Dimas%20Rizqi%20Dwiaji | D12: =Pengaturan!$B$4&CHAR(10)&CHAR(10)&"Kepada Yth."&CHAR(10)&"Bapak/Ibu/Saudara/i"&CHAR(10)&"*"&TRIM(A12)&"*"&CHAR(10)&CHAR(10)&Pengaturan!$B$5&CHAR(10)&Pengaturan!$B$3&"?to="&SUBSTITUTE(SUBSTITUTE(SUBSTITUTE(TRIM(A12),"%","%25"),"&","%26")," ","%20")&CHAR(10)&CHAR(10)&Pengaturan!$B$6 -> Dengan hormat, Kepada Yth. Bapak/Ibu/Saudara/i *Dimas Rizqi Dwiaji* Tanpa mengurangi rasa hormat, perkenankan kami mengundang Bapak/Ibu/Saudara/i untuk menghadiri acara pernikahan kami. Berikut link undangan untuk info lengkap acara: https://weddingditonike.vercel.app/?to=Dimas%20Rizqi%20Dwiaji Merupakan suatu kebahagiaan bagi kami apabila Bapak/Ibu/Saudara/i berkenan hadir dan memberikan doa restu. Terima kasih. Kami yang berbahagia, Dito & Nike
A13: Dito Alfarizi | C13: =HYPERLINK(Pengaturan!$B$3&"?to="&SUBSTITUTE(SUBSTITUTE(SUBSTITUTE(TRIM(A13),"%","%25"),"&","%26")," ","%20"),Pengaturan!$B$3&"?to="&SUBSTITUTE(SUBSTITUTE(SUBSTITUTE(TRIM(A13),"%","%25"),"&","%26")," ","%20")) -> https://weddingditonike.vercel.app/?to=Dito%20Alfarizi | D13: =Pengaturan!$B$4&CHAR(10)&CHAR(10)&"Kepada Yth."&CHAR(10)&"Bapak/Ibu/Saudara/i"&CHAR(10)&"*"&TRIM(A13)&"*"&CHAR(10)&CHAR(10)&Pengaturan!$B$5&CHAR(10)&Pengaturan!$B$3&"?to="&SUBSTITUTE(SUBSTITUTE(SUBSTITUTE(TRIM(A13),"%","%25"),"&","%26")," ","%20")&CHAR(10)&CHAR(10)&Pengaturan!$B$6 -> Dengan hormat, Kepada Yth. Bapak/Ibu/Saudara/i *Dito Alfarizi* Tanpa mengurangi rasa hormat, perkenankan kami mengundang Bapak/Ibu/Saudara/i untuk menghadiri acara pernikahan kami. Berikut link undangan untuk info lengkap acara: https://weddingditonike.vercel.app/?to=Dito%20Alfarizi Merupakan suatu kebahagiaan bagi kami apabila Bapak/Ibu/Saudara/i berkenan hadir dan memberikan doa restu. Terima kasih. Kami yang berbahagia, Dito & Nike
A14: Fatchurrosy | C14: =HYPERLINK(Pengaturan!$B$3&"?to="&SUBSTITUTE(SUBSTITUTE(SUBSTITUTE(TRIM(A14),"%","%25"),"&","%26")," ","%20"),Pengaturan!$B$3&"?to="&SUBSTITUTE(SUBSTITUTE(SUBSTITUTE(TRIM(A14),"%","%25"),"&","%26")," ","%20")) -> https://weddingditonike.vercel.app/?to=Fatchurrosy | D14: =Pengaturan!$B$4&CHAR(10)&CHAR(10)&"Kepada Yth."&CHAR(10)&"Bapak/Ibu/Saudara/i"&CHAR(10)&"*"&TRIM(A14)&"*"&CHAR(10)&CHAR(10)&Pengaturan!$B$5&CHAR(10)&Pengaturan!$B$3&"?to="&SUBSTITUTE(SUBSTITUTE(SUBSTITUTE(TRIM(A14),"%","%25"),"&","%26")," ","%20")&CHAR(10)&CHAR(10)&Pengaturan!$B$6 -> Dengan hormat, Kepada Yth. Bapak/Ibu/Saudara/i *Fatchurrosy* Tanpa mengurangi rasa hormat, perkenankan kami mengundang Bapak/Ibu/Saudara/i untuk menghadiri acara pernikahan kami. Berikut link undangan untuk info lengkap acara: https://weddingditonike.vercel.app/?to=Fatchurrosy Merupakan suatu kebahagiaan bagi kami apabila Bapak/Ibu/Saudara/i berkenan hadir dan memberikan doa restu. Terima kasih. Kami yang berbahagia, Dito & Nike
A15: Friska Uli Junita Astuty Sianturi | C15: =HYPERLINK(Pengaturan!$B$3&"?to="&SUBSTITUTE(SUBSTITUTE(SUBSTITUTE(TRIM(A15),"%","%25"),"&","%26")," ","%20"),Pengaturan!$B$3&"?to="&SUBSTITUTE(SUBSTITUTE(SUBSTITUTE(TRIM(A15),"%","%25"),"&","%26")," ","%20")) -> https://weddingditonike.vercel.app/?to=Friska%20Uli%20Junita%20Astuty%20Sianturi | D15: =Pengaturan!$B$4&CHAR(10)&CHAR(10)&"Kepada Yth."&CHAR(10)&"Bapak/Ibu/Saudara/i"&CHAR(10)&"*"&TRIM(A15)&"*"&CHAR(10)&CHAR(10)&Pengaturan!$B$5&CHAR(10)&Pengaturan!$B$3&"?to="&SUBSTITUTE(SUBSTITUTE(SUBSTITUTE(TRIM(A15),"%","%25"),"&","%26")," ","%20")&CHAR(10)&CHAR(10)&Pengaturan!$B$6 -> Dengan hormat, Kepada Yth. Bapak/Ibu/Saudara/i *Friska Uli Junita Astuty Sianturi* Tanpa mengurangi rasa hormat, perkenankan kami mengundang Bapak/Ibu/Saudara/i untuk menghadiri acara pernikahan kami. Berikut link undangan untuk info lengkap acara: https://weddingditonike.vercel.app/?to=Friska%20Uli%20Junita%20Astuty%20Sianturi Merupakan suatu kebahagiaan bagi kami apabila Bapak/Ibu/Saudara/i berkenan hadir dan memberikan doa restu. Terima kasih. Kami yang berbahagia, Dito & Nike
... A22: Wahyudin | C22: =HYPERLINK(Pengaturan!$B$3&"?to="&SUBSTITUTE(SUBSTITUTE(SUBSTITUTE(TRIM(A22),"%","%25"),"&","%26")," ","%20"),Pengaturan!$B$3&"?to="&SUBSTITUTE(SUBSTITUTE(SUBSTITUTE(TRIM(A22),"%","%25"),"&","%26")," ","%20")) -> https://weddingditonike.vercel.app/?to=Wahyudin | D22: =Pengaturan!$B$4&CHAR(10)&CHAR(10)&"Kepada Yth."&CHAR(10)&"Bapak/Ibu/Saudara/i"&CHAR(10)&"*"&TRIM(A22)&"*"&CHAR(10)&CHAR(10)&Pengaturan!$B$5&CHAR(10)&Pengaturan!$B$3&"?to="&SUBSTITUTE(SUBSTITUTE(SUBSTITUTE(TRIM(A22),"%","%25"),"&","%26")," ","%20")&CHAR(10)&CHAR(10)&Pengaturan!$B$6 -> Dengan hormat, Kepada Yth. Bapak/Ibu/Saudara/i *Wahyudin* Tanpa mengurangi rasa hormat, perkenankan kami mengundang Bapak/Ibu/Saudara/i untuk menghadiri acara pernikahan kami. Berikut link undangan untuk info lengkap acara: https://weddingditonike.vercel.app/?to=Wahyudin Merupakan suatu kebahagiaan bagi kami apabila Bapak/Ibu/Saudara/i berkenan hadir dan memberikan doa restu. Terima kasih. Kami yang berbahagia, Dito & Nike
A23: Yuli Suryani | B23: Bagian Pemindahtanganan, Pemusnahan, dan Penghapusan BMN | C23: =HYPERLINK(Pengaturan!$B$3&"?to="&SUBSTITUTE(SUBSTITUTE(SUBSTITUTE(TRIM(A23),"%","%25"),"&","%26")," ","%20"),Pengaturan!$B$3&"?to="&SUBSTITUTE(SUBSTITUTE(SUBSTITUTE(TRIM(A23),"%","%25"),"&","%26")," ","%20")) -> https://weddingditonike.vercel.app/?to=Yuli%20Suryani | D23: =Pengaturan!$B$4&CHAR(10)&CHAR(10)&"Kepada Yth."&CHAR(10)&"Bapak/Ibu/Saudara/i"&CHAR(10)&"*"&TRIM(A23)&"*"&CHAR(10)&CHAR(10)&Pengaturan!$B$5&CHAR(10)&Pengaturan!$B$3&"?to="&SUBSTITUTE(SUBSTITUTE(SUBSTITUTE(TRIM(A23),"%","%25"),"&","%26")," ","%20")&CHAR(10)&CHAR(10)&Pengaturan!$B$6 -> Dengan hormat, Kepada Yth. Bapak/Ibu/Saudara/i *Yuli Suryani* Tanpa mengurangi rasa hormat, perkenankan kami mengundang Bapak/Ibu/Saudara/i untuk menghadiri acara pernikahan kami. Berikut link undangan untuk info lengkap acara: https://weddingditonike.vercel.app/?to=Yuli%20Suryani Merupakan suatu kebahagiaan bagi kami apabila Bapak/Ibu/Saudara/i berkenan hadir dan memberikan doa restu. Terima kasih. Kami yang berbahagia, Dito & Nike
A24: Agus Prayoga | C24: =HYPERLINK(Pengaturan!$B$3&"?to="&SUBSTITUTE(SUBSTITUTE(SUBSTITUTE(TRIM(A24),"%","%25"),"&","%26")," ","%20"),Pengaturan!$B$3&"?to="&SUBSTITUTE(SUBSTITUTE(SUBSTITUTE(TRIM(A24),"%","%25"),"&","%26")," ","%20")) -> https://weddingditonike.vercel.app/?to=Agus%20Prayoga | D24: =Pengaturan!$B$4&CHAR(10)&CHAR(10)&"Kepada Yth."&CHAR(10)&"Bapak/Ibu/Saudara/i"&CHAR(10)&"*"&TRIM(A24)&"*"&CHAR(10)&CHAR(10)&Pengaturan!$B$5&CHAR(10)&Pengaturan!$B$3&"?to="&SUBSTITUTE(SUBSTITUTE(SUBSTITUTE(TRIM(A24),"%","%25"),"&","%26")," ","%20")&CHAR(10)&CHAR(10)&Pengaturan!$B$6 -> Dengan hormat, Kepada Yth. Bapak/Ibu/Saudara/i *Agus Prayoga* Tanpa mengurangi rasa hormat, perkenankan kami mengundang Bapak/Ibu/Saudara/i untuk menghadiri acara pernikahan kami. Berikut link undangan untuk info lengkap acara: https://weddingditonike.vercel.app/?to=Agus%20Prayoga Merupakan suatu kebahagiaan bagi kami apabila Bapak/Ibu/Saudara/i berkenan hadir dan memberikan doa restu. Terima kasih. Kami yang berbahagia, Dito & Nike
A25: Beny Rudianto | C25: =HYPERLINK(Pengaturan!$B$3&"?to="&SUBSTITUTE(SUBSTITUTE(SUBSTITUTE(TRIM(A25),"%","%25"),"&","%26")," ","%20"),Pengaturan!$B$3&"?to="&SUBSTITUTE(SUBSTITUTE(SUBSTITUTE(TRIM(A25),"%","%25"),"&","%26")," ","%20")) -> https://weddingditonike.vercel.app/?to=Beny%20Rudianto | D25: =Pengaturan!$B$4&CHAR(10)&CHAR(10)&"Kepada Yth."&CHAR(10)&"Bapak/Ibu/Saudara/i"&CHAR(10)&"*"&TRIM(A25)&"*"&CHAR(10)&CHAR(10)&Pengaturan!$B$5&CHAR(10)&Pengaturan!$B$3&"?to="&SUBSTITUTE(SUBSTITUTE(SUBSTITUTE(TRIM(A25),"%","%25"),"&","%26")," ","%20")&CHAR(10)&CHAR(10)&Pengaturan!$B$6 -> Dengan hormat, Kepada Yth. Bapak/Ibu/Saudara/i *Beny Rudianto* Tanpa mengurangi rasa hormat, perkenankan kami mengundang Bapak/Ibu/Saudara/i untuk menghadiri acara pernikahan kami. Berikut link undangan untuk info lengkap acara: https://weddingditonike.vercel.app/?to=Beny%20Rudianto Merupakan suatu kebahagiaan bagi kami apabila Bapak/Ibu/Saudara/i berkenan hadir dan memberikan doa restu. Terima kasih. Kami yang berbahagia, Dito & Nike
A26: Carlos Tua March Siburian | C26: =HYPERLINK(Pengaturan!$B$3&"?to="&SUBSTITUTE(SUBSTITUTE(SUBSTITUTE(TRIM(A26),"%","%25"),"&","%26")," ","%20"),Pengaturan!$B$3&"?to="&SUBSTITUTE(SUBSTITUTE(SUBSTITUTE(TRIM(A26),"%","%25"),"&","%26")," ","%20")) -> https://weddingditonike.vercel.app/?to=Carlos%20Tua%20March%20Siburian | D26: =Pengaturan!$B$4&CHAR(10)&CHAR(10)&"Kepada Yth."&CHAR(10)&"Bapak/Ibu/Saudara/i"&CHAR(10)&"*"&TRIM(A26)&"*"&CHAR(10)&CHAR(10)&Pengaturan!$B$5&CHAR(10)&Pengaturan!$B$3&"?to="&SUBSTITUTE(SUBSTITUTE(SUBSTITUTE(TRIM(A26),"%","%25"),"&","%26")," ","%20")&CHAR(10)&CHAR(10)&Pengaturan!$B$6 -> Dengan hormat, Kepada Yth. Bapak/Ibu/Saudara/i *Carlos Tua March Siburian* Tanpa mengurangi rasa hormat, perkenankan kami mengundang Bapak/Ibu/Saudara/i untuk menghadiri acara pernikahan kami. Berikut link undangan untuk info lengkap acara: https://weddingditonike.vercel.app/?to=Carlos%20Tua%20March%20Siburian Merupakan suatu kebahagiaan bagi kami apabila Bapak/Ibu/Saudara/i berkenan hadir dan memberikan doa restu. Terima kasih. Kami yang berbahagia, Dito & Nike
A27: Dawiyah | C27: =HYPERLINK(Pengaturan!$B$3&"?to="&SUBSTITUTE(SUBSTITUTE(SUBSTITUTE(TRIM(A27),"%","%25"),"&","%26")," ","%20"),Pengaturan!$B$3&"?to="&SUBSTITUTE(SUBSTITUTE(SUBSTITUTE(TRIM(A27),"%","%25"),"&","%26")," ","%20")) -> https://weddingditonike.vercel.app/?to=Dawiyah | D27: =Pengaturan!$B$4&CHAR(10)&CHAR(10)&"Kepada Yth."&CHAR(10)&"Bapak/Ibu/Saudara/i"&CHAR(10)&"*"&TRIM(A27)&"*"&CHAR(10)&CHAR(10)&Pengaturan!$B$5&CHAR(10)&Pengaturan!$B$3&"?to="&SUBSTITUTE(SUBSTITUTE(SUBSTITUTE(TRIM(A27),"%","%25"),"&","%26")," ","%20")&CHAR(10)&CHAR(10)&Pengaturan!$B$6 -> Dengan hormat, Kepada Yth. Bapak/Ibu/Saudara/i *Dawiyah* Tanpa mengurangi rasa hormat, perkenankan kami mengundang Bapak/Ibu/Saudara/i untuk menghadiri acara pernikahan kami. Berikut link undangan untuk info lengkap acara: https://weddingditonike.vercel.app/?to=Dawiyah Merupakan suatu kebahagiaan bagi kami apabila Bapak/Ibu/Saudara/i berkenan hadir dan memberikan doa restu. Terima kasih. Kami yang berbahagia, Dito & Nike
A28: Fajar Nugraha | C28: =HYPERLINK(Pengaturan!$B$3&"?to="&SUBSTITUTE(SUBSTITUTE(SUBSTITUTE(TRIM(A28),"%","%25"),"&","%26")," ","%20"),Pengaturan!$B$3&"?to="&SUBSTITUTE(SUBSTITUTE(SUBSTITUTE(TRIM(A28),"%","%25"),"&","%26")," ","%20")) -> https://weddingditonike.vercel.app/?to=Fajar%20Nugraha | D28: =Pengaturan!$B$4&CHAR(10)&CHAR(10)&"Kepada Yth."&CHAR(10)&"Bapak/Ibu/Saudara/i"&CHAR(10)&"*"&TRIM(A28)&"*"&CHAR(10)&CHAR(10)&Pengaturan!$B$5&CHAR(10)&Pengaturan!$B$3&"?to="&SUBSTITUTE(SUBSTITUTE(SUBSTITUTE(TRIM(A28),"%","%25"),"&","%26")," ","%20")&CHAR(10)&CHAR(10)&Pengaturan!$B$6 -> Dengan hormat, Kepada Yth. Bapak/Ibu/Saudara/i *Fajar Nugraha* Tanpa mengurangi rasa hormat, perkenankan kami mengundang Bapak/Ibu/Saudara/i untuk menghadiri acara pernikahan kami. Berikut link undangan untuk info lengkap acara: https://weddingditonike.vercel.app/?to=Fajar%20Nugraha Merupakan suatu kebahagiaan bagi kami apabila Bapak/Ibu/Saudara/i berkenan hadir dan memberikan doa restu. Terima kasih. Kami yang berbahagia, Dito & Nike
A29: Hafizh Zaghlul Rizal | C29: =HYPERLINK(Pengaturan!$B$3&"?to="&SUBSTITUTE(SUBSTITUTE(SUBSTITUTE(TRIM(A29),"%","%25"),"&","%26")," ","%20"),Pengaturan!$B$3&"?to="&SUBSTITUTE(SUBSTITUTE(SUBSTITUTE(TRIM(A29),"%","%25"),"&","%26")," ","%20")) -> https://weddingditonike.vercel.app/?to=Hafizh%20Zaghlul%20Rizal | D29: =Pengaturan!$B$4&CHAR(10)&CHAR(10)&"Kepada Yth."&CHAR(10)&"Bapak/Ibu/Saudara/i"&CHAR(10)&"*"&TRIM(A29)&"*"&CHAR(10)&CHAR(10)&Pengaturan!$B$5&CHAR(10)&Pengaturan!$B$3&"?to="&SUBSTITUTE(SUBSTITUTE(SUBSTITUTE(TRIM(A29),"%","%25"),"&","%26")," ","%20")&CHAR(10)&CHAR(10)&Pengaturan!$B$6 -> Dengan hormat, Kepada Yth. Bapak/Ibu/Saudara/i *Hafizh Zaghlul Rizal* Tanpa mengurangi rasa hormat, perkenankan kami mengundang Bapak/Ibu/Saudara/i untuk menghadiri acara pernikahan kami. Berikut link undangan untuk info lengkap acara: https://weddingditonike.vercel.app/?to=Hafizh%20Zaghlul%20Rizal Merupakan suatu kebahagiaan bagi kami apabila Bapak/Ibu/Saudara/i berkenan hadir dan memberikan doa restu. Terima kasih. Kami yang berbahagia, Dito & Nike
A30: Hendri Febrianto | C30: =HYPERLINK(Pengaturan!$B$3&"?to="&SUBSTITUTE(SUBSTITUTE(SUBSTITUTE(TRIM(A30),"%","%25"),"&","%26")," ","%20"),Pengaturan!$B$3&"?to="&SUBSTITUTE(SUBSTITUTE(SUBSTITUTE(TRIM(A30),"%","%25"),"&","%26")," ","%20")) -> https://weddingditonike.vercel.app/?to=Hendri%20Febrianto | D30: =Pengaturan!$B$4&CHAR(10)&CHAR(10)&"Kepada Yth."&CHAR(10)&"Bapak/Ibu/Saudara/i"&CHAR(10)&"*"&TRIM(A30)&"*"&CHAR(10)&CHAR(10)&Pengaturan!$B$5&CHAR(10)&Pengaturan!$B$3&"?to="&SUBSTITUTE(SUBSTITUTE(SUBSTITUTE(TRIM(A30),"%","%25"),"&","%26")," ","%20")&CHAR(10)&CHAR(10)&Pengaturan!$B$6 -> Dengan hormat, Kepada Yth. Bapak/Ibu/Saudara/i *Hendri Febrianto* Tanpa mengurangi rasa hormat, perkenankan kami mengundang Bapak/Ibu/Saudara/i untuk menghadiri acara pernikahan kami. Berikut link undangan untuk info lengkap acara: https://weddingditonike.vercel.app/?to=Hendri%20Febrianto Merupakan suatu kebahagiaan bagi kami apabila Bapak/Ibu/Saudara/i berkenan hadir dan memberikan doa restu. Terima kasih. Kami yang berbahagia, Dito & Nike
A31: Hutamaning Margo Raharjo | C31: =HYPERLINK(Pengaturan!$B$3&"?to="&SUBSTITUTE(SUBSTITUTE(SUBSTITUTE(TRIM(A31),"%","%25"),"&","%26")," ","%20"),Pengaturan!$B$3&"?to="&SUBSTITUTE(SUBSTITUTE(SUBSTITUTE(TRIM(A31),"%","%25"),"&","%26")," ","%20")) -> https://weddingditonike.vercel.app/?to=Hutamaning%20Margo%20Raharjo | D31: =Pengaturan!$B$4&CHAR(10)&CHAR(10)&"Kepada Yth."&CHAR(10)&"Bapak/Ibu/Saudara/i"&CHAR(10)&"*"&TRIM(A31)&"*"&CHAR(10)&CHAR(10)&Pengaturan!$B$5&CHAR(10)&Pengaturan!$B$3&"?to="&SUBSTITUTE(SUBSTITUTE(SUBSTITUTE(TRIM(A31),"%","%25"),"&","%26")," ","%20")&CHAR(10)&CHAR(10)&Pengaturan!$B$6 -> Dengan hormat, Kepada Yth. Bapak/Ibu/Saudara/i *Hutamaning Margo Raharjo* Tanpa mengurangi rasa hormat, perkenankan kami mengundang Bapak/Ibu/Saudara/i untuk menghadiri acara pernikahan kami. Berikut link undangan untuk info lengkap acara: https://weddingditonike.vercel.app/?to=Hutamaning%20Margo%20Raharjo Merupakan suatu kebahagiaan bagi kami apabila Bapak/Ibu/Saudara/i berkenan hadir dan memberikan doa restu. Terima kasih. Kami yang berbahagia, Dito & Nike
A32: Isabela Reksa Dini | C32: =HYPERLINK(Pengaturan!$B$3&"?to="&SUBSTITUTE(SUBSTITUTE(SUBSTITUTE(TRIM(A32),"%","%25"),"&","%26")," ","%20"),Pengaturan!$B$3&"?to="&SUBSTITUTE(SUBSTITUTE(SUBSTITUTE(TRIM(A32),"%","%25"),"&","%26")," ","%20")) -> https://weddingditonike.vercel.app/?to=Isabela%20Reksa%20Dini | D32: =Pengaturan!$B$4&CHAR(10)&CHAR(10)&"Kepada Yth."&CHAR(10)&"Bapak/Ibu/Saudara/i"&CHAR(10)&"*"&TRIM(A32)&"*"&CHAR(10)&CHAR(10)&Pengaturan!$B$5&CHAR(10)&Pengaturan!$B$3&"?to="&SUBSTITUTE(SUBSTITUTE(SUBSTITUTE(TRIM(A32),"%","%25"),"&","%26")," ","%20")&CHAR(10)&CHAR(10)&Pengaturan!$B$6 -> Dengan hormat, Kepada Yth. Bapak/Ibu/Saudara/i *Isabela Reksa Dini* Tanpa mengurangi rasa hormat, perkenankan kami mengundang Bapak/Ibu/Saudara/i untuk menghadiri acara pernikahan kami. Berikut link undangan untuk info lengkap acara: https://weddingditonike.vercel.app/?to=Isabela%20Reksa%20Dini Merupakan suatu kebahagiaan bagi kami apabila Bapak/Ibu/Saudara/i berkenan hadir dan memberikan doa restu. Terima kasih. Kami yang berbahagia, Dito & Nike
A33: Lia Yulianti | C33: =HYPERLINK(Pengaturan!$B$3&"?to="&SUBSTITUTE(SUBSTITUTE(SUBSTITUTE(TRIM(A33),"%","%25"),"&","%26")," ","%20"),Pengaturan!$B$3&"?to="&SUBSTITUTE(SUBSTITUTE(SUBSTITUTE(TRIM(A33),"%","%25"),"&","%26")," ","%20")) -> https://weddingditonike.vercel.app/?to=Lia%20Yulianti | D33: =Pengaturan!$B$4&CHAR(10)&CHAR(10)&"Kepada Yth."&CHAR(10)&"Bapak/Ibu/Saudara/i"&CHAR(10)&"*"&TRIM(A33)&"*"&CHAR(10)&CHAR(10)&Pengaturan!$B$5&CHAR(10)&Pengaturan!$B$3&"?to="&SUBSTITUTE(SUBSTITUTE(SUBSTITUTE(TRIM(A33),"%","%25"),"&","%26")," ","%20")&CHAR(10)&CHAR(10)&Pengaturan!$B$6 -> Dengan hormat, Kepada Yth. Bapak/Ibu/Saudara/i *Lia Yulianti* Tanpa mengurangi rasa hormat, perkenankan kami mengundang Bapak/Ibu/Saudara/i untuk menghadiri acara pernikahan kami. Berikut link undangan untuk info lengkap acara: https://weddingditonike.vercel.app/?to=Lia%20Yulianti Merupakan suatu kebahagiaan bagi kami apabila Bapak/Ibu/Saudara/i berkenan hadir dan memberikan doa restu. Terima kasih. Kami yang berbahagia, Dito & Nike
A34: Nail Rizqi Afwanadli Purba | C34: =HYPERLINK(Pengaturan!$B$3&"?to="&SUBSTITUTE(SUBSTITUTE(SUBSTITUTE(TRIM(A34),"%","%25"),"&","%26")," ","%20"),Pengaturan!$B$3&"?to="&SUBSTITUTE(SUBSTITUTE(SUBSTITUTE(TRIM(A34),"%","%25"),"&","%26")," ","%20")) -> https://weddingditonike.vercel.app/?to=Nail%20Rizqi%20Afwanadli%20Purba | D34: =Pengaturan!$B$4&CHAR(10)&CHAR(10)&"Kepada Yth."&CHAR(10)&"Bapak/Ibu/Saudara/i"&CHAR(10)&"*"&TRIM(A34)&"*"&CHAR(10)&CHAR(10)&Pengaturan!$B$5&CHAR(10)&Pengaturan!$B$3&"?to="&SUBSTITUTE(SUBSTITUTE(SUBSTITUTE(TRIM(A34),"%","%25"),"&","%26")," ","%20")&CHAR(10)&CHAR(10)&Pengaturan!$B$6 -> Dengan hormat, Kepada Yth. Bapak/Ibu/Saudara/i *Nail Rizqi Afwanadli Purba* Tanpa mengurangi rasa hormat, perkenankan kami mengundang Bapak/Ibu/Saudara/i untuk menghadiri acara pernikahan kami. Berikut link undangan untuk info lengkap acara: https://weddingditonike.vercel.app/?to=Nail%20Rizqi%20Afwanadli%20Purba Merupakan suatu kebahagiaan bagi kami apabila Bapak/Ibu/Saudara/i berkenan hadir dan memberikan doa restu. Terima kasih. Kami yang berbahagia, Dito & Nike
A35: Rayi Setyaningsih | C35: =HYPERLINK(Pengaturan!$B$3&"?to="&SUBSTITUTE(SUBSTITUTE(SUBSTITUTE(TRIM(A35),"%","%25"),"&","%26")," ","%20"),Pengaturan!$B$3&"?to="&SUBSTITUTE(SUBSTITUTE(SUBSTITUTE(TRIM(A35),"%","%25"),"&","%26")," ","%20")) -> https://weddingditonike.vercel.app/?to=Rayi%20Setyaningsih | D35: =Pengaturan!$B$4&CHAR(10)&CHAR(10)&"Kepada Yth."&CHAR(10)&"Bapak/Ibu/Saudara/i"&CHAR(10)&"*"&TRIM(A35)&"*"&CHAR(10)&CHAR(10)&Pengaturan!$B$5&CHAR(10)&Pengaturan!$B$3&"?to="&SUBSTITUTE(SUBSTITUTE(SUBSTITUTE(TRIM(A35),"%","%25"),"&","%26")," ","%20")&CHAR(10)&CHAR(10)&Pengaturan!$B$6 -> Dengan hormat, Kepada Yth. Bapak/Ibu/Saudara/i *Rayi Setyaningsih* Tanpa mengurangi rasa hormat, perkenankan kami mengundang Bapak/Ibu/Saudara/i untuk menghadiri acara pernikahan kami. Berikut link undangan untuk info lengkap acara: https://weddingditonike.vercel.app/?to=Rayi%20Setyaningsih Merupakan suatu kebahagiaan bagi kami apabila Bapak/Ibu/Saudara/i berkenan hadir dan memberikan doa restu. Terima kasih. Kami yang berbahagia, Dito & Nike
... A39: Yujiyono | C39: =HYPERLINK(Pengaturan!$B$3&"?to="&SUBSTITUTE(SUBSTITUTE(SUBSTITUTE(TRIM(A39),"%","%25"),"&","%26")," ","%20"),Pengaturan!$B$3&"?to="&SUBSTITUTE(SUBSTITUTE(SUBSTITUTE(TRIM(A39),"%","%25"),"&","%26")," ","%20")) -> https://weddingditonike.vercel.app/?to=Yujiyono | D39: =Pengaturan!$B$4&CHAR(10)&CHAR(10)&"Kepada Yth."&CHAR(10)&"Bapak/Ibu/Saudara/i"&CHAR(10)&"*"&TRIM(A39)&"*"&CHAR(10)&CHAR(10)&Pengaturan!$B$5&CHAR(10)&Pengaturan!$B$3&"?to="&SUBSTITUTE(SUBSTITUTE(SUBSTITUTE(TRIM(A39),"%","%25"),"&","%26")," ","%20")&CHAR(10)&CHAR(10)&Pengaturan!$B$6 -> Dengan hormat, Kepada Yth. Bapak/Ibu/Saudara/i *Yujiyono* Tanpa mengurangi rasa hormat, perkenankan kami mengundang Bapak/Ibu/Saudara/i untuk menghadiri acara pernikahan kami. Berikut link undangan untuk info lengkap acara: https://weddingditonike.vercel.app/?to=Yujiyono Merupakan suatu kebahagiaan bagi kami apabila Bapak/Ibu/Saudara/i berkenan hadir dan memberikan doa restu. Terima kasih. Kami yang berbahagia, Dito & Nike
A40: Gamal Maulian | B40: Bagian Penatausahaan, Penggunaan, dan RKBMN | C40: =HYPERLINK(Pengaturan!$B$3&"?to="&SUBSTITUTE(SUBSTITUTE(SUBSTITUTE(TRIM(A40),"%","%25"),"&","%26")," ","%20"),Pengaturan!$B$3&"?to="&SUBSTITUTE(SUBSTITUTE(SUBSTITUTE(TRIM(A40),"%","%25"),"&","%26")," ","%20")) -> https://weddingditonike.vercel.app/?to=Gamal%20Maulian | D40: =Pengaturan!$B$4&CHAR(10)&CHAR(10)&"Kepada Yth."&CHAR(10)&"Bapak/Ibu/Saudara/i"&CHAR(10)&"*"&TRIM(A40)&"*"&CHAR(10)&CHAR(10)&Pengaturan!$B$5&CHAR(10)&Pengaturan!$B$3&"?to="&SUBSTITUTE(SUBSTITUTE(SUBSTITUTE(TRIM(A40),"%","%25"),"&","%26")," ","%20")&CHAR(10)&CHAR(10)&Pengaturan!$B$6 -> Dengan hormat, Kepada Yth. Bapak/Ibu/Saudara/i *Gamal Maulian* Tanpa mengurangi rasa hormat, perkenankan kami mengundang Bapak/Ibu/Saudara/i untuk menghadiri acara pernikahan kami. Berikut link undangan untuk info lengkap acara: https://weddingditonike.vercel.app/?to=Gamal%20Maulian Merupakan suatu kebahagiaan bagi kami apabila Bapak/Ibu/Saudara/i berkenan hadir dan memberikan doa restu. Terima kasih. Kami yang berbahagia, Dito & Nike
A41: Afiifah Eka Prastiyani | C41: =HYPERLINK(Pengaturan!$B$3&"?to="&SUBSTITUTE(SUBSTITUTE(SUBSTITUTE(TRIM(A41),"%","%25"),"&","%26")," ","%20"),Pengaturan!$B$3&"?to="&SUBSTITUTE(SUBSTITUTE(SUBSTITUTE(TRIM(A41),"%","%25"),"&","%26")," ","%20")) -> https://weddingditonike.vercel.app/?to=Afiifah%20Eka%20Prastiyani | D41: =Pengaturan!$B$4&CHAR(10)&CHAR(10)&"Kepada Yth."&CHAR(10)&"Bapak/Ibu/Saudara/i"&CHAR(10)&"*"&TRIM(A41)&"*"&CHAR(10)&CHAR(10)&Pengaturan!$B$5&CHAR(10)&Pengaturan!$B$3&"?to="&SUBSTITUTE(SUBSTITUTE(SUBSTITUTE(TRIM(A41),"%","%25"),"&","%26")," ","%20")&CHAR(10)&CHAR(10)&Pengaturan!$B$6 -> Dengan hormat, Kepada Yth. Bapak/Ibu/Saudara/i *Afiifah Eka Prastiyani* Tanpa mengurangi rasa hormat, perkenankan kami mengundang Bapak/Ibu/Saudara/i untuk menghadiri acara pernikahan kami. Berikut link undangan untuk info lengkap acara: https://weddingditonike.vercel.app/?to=Afiifah%20Eka%20Prastiyani Merupakan suatu kebahagiaan bagi kami apabila Bapak/Ibu/Saudara/i berkenan hadir dan memberikan doa restu. Terima kasih. Kami yang berbahagia, Dito & Nike
A42: Ahmad Maulana | C42: =HYPERLINK(Pengaturan!$B$3&"?to="&SUBSTITUTE(SUBSTITUTE(SUBSTITUTE(TRIM(A42),"%","%25"),"&","%26")," ","%20"),Pengaturan!$B$3&"?to="&SUBSTITUTE(SUBSTITUTE(SUBSTITUTE(TRIM(A42),"%","%25"),"&","%26")," ","%20")) -> https://weddingditonike.vercel.app/?to=Ahmad%20Maulana | D42: =Pengaturan!$B$4&CHAR(10)&CHAR(10)&"Kepada Yth."&CHAR(10)&"Bapak/Ibu/Saudara/i"&CHAR(10)&"*"&TRIM(A42)&"*"&CHAR(10)&CHAR(10)&Pengaturan!$B$5&CHAR(10)&Pengaturan!$B$3&"?to="&SUBSTITUTE(SUBSTITUTE(SUBSTITUTE(TRIM(A42),"%","%25"),"&","%26")," ","%20")&CHAR(10)&CHAR(10)&Pengaturan!$B$6 -> Dengan hormat, Kepada Yth. Bapak/Ibu/Saudara/i *Ahmad Maulana* Tanpa mengurangi rasa hormat, perkenankan kami mengundang Bapak/Ibu/Saudara/i untuk menghadiri acara pernikahan kami. Berikut link undangan untuk info lengkap acara: https://weddingditonike.vercel.app/?to=Ahmad%20Maulana Merupakan suatu kebahagiaan bagi kami apabila Bapak/Ibu/Saudara/i berkenan hadir dan memberikan doa restu. Terima kasih. Kami yang berbahagia, Dito & Nike
A43: Ahmad Zaki | C43: =HYPERLINK(Pengaturan!$B$3&"?to="&SUBSTITUTE(SUBSTITUTE(SUBSTITUTE(TRIM(A43),"%","%25"),"&","%26")," ","%20"),Pengaturan!$B$3&"?to="&SUBSTITUTE(SUBSTITUTE(SUBSTITUTE(TRIM(A43),"%","%25"),"&","%26")," ","%20")) -> https://weddingditonike.vercel.app/?to=Ahmad%20Zaki | D43: =Pengaturan!$B$4&CHAR(10)&CHAR(10)&"Kepada Yth."&CHAR(10)&"Bapak/Ibu/Saudara/i"&CHAR(10)&"*"&TRIM(A43)&"*"&CHAR(10)&CHAR(10)&Pengaturan!$B$5&CHAR(10)&Pengaturan!$B$3&"?to="&SUBSTITUTE(SUBSTITUTE(SUBSTITUTE(TRIM(A43),"%","%25"),"&","%26")," ","%20")&CHAR(10)&CHAR(10)&Pengaturan!$B$6 -> Dengan hormat, Kepada Yth. Bapak/Ibu/Saudara/i *Ahmad Zaki* Tanpa mengurangi rasa hormat, perkenankan kami mengundang Bapak/Ibu/Saudara/i untuk menghadiri acara pernikahan kami. Berikut link undangan untuk info lengkap acara: https://weddingditonike.vercel.app/?to=Ahmad%20Zaki Merupakan suatu kebahagiaan bagi kami apabila Bapak/Ibu/Saudara/i berkenan hadir dan memberikan doa restu. Terima kasih. Kami yang berbahagia, Dito & Nike
A44: Amir Husein Sarumpaet | C44: =HYPERLINK(Pengaturan!$B$3&"?to="&SUBSTITUTE(SUBSTITUTE(SUBSTITUTE(TRIM(A44),"%","%25"),"&","%26")," ","%20"),Pengaturan!$B$3&"?to="&SUBSTITUTE(SUBSTITUTE(SUBSTITUTE(TRIM(A44),"%","%25"),"&","%26")," ","%20")) -> https://weddingditonike.vercel.app/?to=Amir%20Husein%20Sarumpaet | D44: =Pengaturan!$B$4&CHAR(10)&CHAR(10)&"Kepada Yth."&CHAR(10)&"Bapak/Ibu/Saudara/i"&CHAR(10)&"*"&TRIM(A44)&"*"&CHAR(10)&CHAR(10)&Pengaturan!$B$5&CHAR(10)&Pengaturan!$B$3&"?to="&SUBSTITUTE(SUBSTITUTE(SUBSTITUTE(TRIM(A44),"%","%25"),"&","%26")," ","%20")&CHAR(10)&CHAR(10)&Pengaturan!$B$6 -> Dengan hormat, Kepada Yth. Bapak/Ibu/Saudara/i *Amir Husein Sarumpaet* Tanpa mengurangi rasa hormat, perkenankan kami mengundang Bapak/Ibu/Saudara/i untuk menghadiri acara pernikahan kami. Berikut link undangan untuk info lengkap acara: https://weddingditonike.vercel.app/?to=Amir%20Husein%20Sarumpaet Merupakan suatu kebahagiaan bagi kami apabila Bapak/Ibu/Saudara/i berkenan hadir dan memberikan doa restu. Terima kasih. Kami yang berbahagia, Dito & Nike
A45: Dita Solihati | C45: =HYPERLINK(Pengaturan!$B$3&"?to="&SUBSTITUTE(SUBSTITUTE(SUBSTITUTE(TRIM(A45),"%","%25"),"&","%26")," ","%20"),Pengaturan!$B$3&"?to="&SUBSTITUTE(SUBSTITUTE(SUBSTITUTE(TRIM(A45),"%","%25"),"&","%26")," ","%20")) -> https://weddingditonike.vercel.app/?to=Dita%20Solihati | D45: =Pengaturan!$B$4&CHAR(10)&CHAR(10)&"Kepada Yth."&CHAR(10)&"Bapak/Ibu/Saudara/i"&CHAR(10)&"*"&TRIM(A45)&"*"&CHAR(10)&CHAR(10)&Pengaturan!$B$5&CHAR(10)&Pengaturan!$B$3&"?to="&SUBSTITUTE(SUBSTITUTE(SUBSTITUTE(TRIM(A45),"%","%25"),"&","%26")," ","%20")&CHAR(10)&CHAR(10)&Pengaturan!$B$6 -> Dengan hormat, Kepada Yth. Bapak/Ibu/Saudara/i *Dita Solihati* Tanpa mengurangi rasa hormat, perkenankan kami mengundang Bapak/Ibu/Saudara/i untuk menghadiri acara pernikahan kami. Berikut link undangan untuk info lengkap acara: https://weddingditonike.vercel.app/?to=Dita%20Solihati Merupakan suatu kebahagiaan bagi kami apabila Bapak/Ibu/Saudara/i berkenan hadir dan memberikan doa restu. Terima kasih. Kami yang berbahagia, Dito & Nike
A46: Fakhri Jauhari Patria | C46: =HYPERLINK(Pengaturan!$B$3&"?to="&SUBSTITUTE(SUBSTITUTE(SUBSTITUTE(TRIM(A46),"%","%25"),"&","%26")," ","%20"),Pengaturan!$B$3&"?to="&SUBSTITUTE(SUBSTITUTE(SUBSTITUTE(TRIM(A46),"%","%25"),"&","%26")," ","%20")) -> https://weddingditonike.vercel.app/?to=Fakhri%20Jauhari%20Patria | D46: =Pengaturan!$B$4&CHAR(10)&CHAR(10)&"Kepada Yth."&CHAR(10)&"Bapak/Ibu/Saudara/i"&CHAR(10)&"*"&TRIM(A46)&"*"&CHAR(10)&CHAR(10)&Pengaturan!$B$5&CHAR(10)&Pengaturan!$B$3&"?to="&SUBSTITUTE(SUBSTITUTE(SUBSTITUTE(TRIM(A46),"%","%25"),"&","%26")," ","%20")&CHAR(10)&CHAR(10)&Pengaturan!$B$6 -> Dengan hormat, Kepada Yth. Bapak/Ibu/Saudara/i *Fakhri Jauhari Patria* Tanpa mengurangi rasa hormat, perkenankan kami mengundang Bapak/Ibu/Saudara/i untuk menghadiri acara pernikahan kami. Berikut link undangan untuk info lengkap acara: https://weddingditonike.vercel.app/?to=Fakhri%20Jauhari%20Patria Merupakan suatu kebahagiaan bagi kami apabila Bapak/Ibu/Saudara/i berkenan hadir dan memberikan doa restu. Terima kasih. Kami yang berbahagia, Dito & Nike
A47: Gd Arya Mahendra Putra | C47: =HYPERLINK(Pengaturan!$B$3&"?to="&SUBSTITUTE(SUBSTITUTE(SUBSTITUTE(TRIM(A47),"%","%25"),"&","%26")," ","%20"),Pengaturan!$B$3&"?to="&SUBSTITUTE(SUBSTITUTE(SUBSTITUTE(TRIM(A47),"%","%25"),"&","%26")," ","%20")) -> https://weddingditonike.vercel.app/?to=Gd%20Arya%20Mahendra%20Putra | D47: =Pengaturan!$B$4&CHAR(10)&CHAR(10)&"Kepada Yth."&CHAR(10)&"Bapak/Ibu/Saudara/i"&CHAR(10)&"*"&TRIM(A47)&"*"&CHAR(10)&CHAR(10)&Pengaturan!$B$5&CHAR(10)&Pengaturan!$B$3&"?to="&SUBSTITUTE(SUBSTITUTE(SUBSTITUTE(TRIM(A47),"%","%25"),"&","%26")," ","%20")&CHAR(10)&CHAR(10)&Pengaturan!$B$6 -> Dengan hormat, Kepada Yth. Bapak/Ibu/Saudara/i *Gd Arya Mahendra Putra* Tanpa mengurangi rasa hormat, perkenankan kami mengundang Bapak/Ibu/Saudara/i untuk menghadiri acara pernikahan kami. Berikut link undangan untuk info lengkap acara: https://weddingditonike.vercel.app/?to=Gd%20Arya%20Mahendra%20Putra Merupakan suatu kebahagiaan bagi kami apabila Bapak/Ibu/Saudara/i berkenan hadir dan memberikan doa restu. Terima kasih. Kami yang berbahagia, Dito & Nike
A48: Hilal Hasbiallah | C48: =HYPERLINK(Pengaturan!$B$3&"?to="&SUBSTITUTE(SUBSTITUTE(SUBSTITUTE(TRIM(A48),"%","%25"),"&","%26")," ","%20"),Pengaturan!$B$3&"?to="&SUBSTITUTE(SUBSTITUTE(SUBSTITUTE(TRIM(A48),"%","%25"),"&","%26")," ","%20")) -> https://weddingditonike.vercel.app/?to=Hilal%20Hasbiallah | D48: =Pengaturan!$B$4&CHAR(10)&CHAR(10)&"Kepada Yth."&CHAR(10)&"Bapak/Ibu/Saudara/i"&CHAR(10)&"*"&TRIM(A48)&"*"&CHAR(10)&CHAR(10)&Pengaturan!$B$5&CHAR(10)&Pengaturan!$B$3&"?to="&SUBSTITUTE(SUBSTITUTE(SUBSTITUTE(TRIM(A48),"%","%25"),"&","%26")," ","%20")&CHAR(10)&CHAR(10)&Pengaturan!$B$6 -> Dengan hormat, Kepada Yth. Bapak/Ibu/Saudara/i *Hilal Hasbiallah* Tanpa mengurangi rasa hormat, perkenankan kami mengundang Bapak/Ibu/Saudara/i untuk menghadiri acara pernikahan kami. Berikut link undangan untuk info lengkap acara: https://weddingditonike.vercel.app/?to=Hilal%20Hasbiallah Merupakan suatu kebahagiaan bagi kami apabila Bapak/Ibu/Saudara/i berkenan hadir dan memberikan doa restu. Terima kasih. Kami yang berbahagia, Dito & Nike
A49: Monika Widiyana | C49: =HYPERLINK(Pengaturan!$B$3&"?to="&SUBSTITUTE(SUBSTITUTE(SUBSTITUTE(TRIM(A49),"%","%25"),"&","%26")," ","%20"),Pengaturan!$B$3&"?to="&SUBSTITUTE(SUBSTITUTE(SUBSTITUTE(TRIM(A49),"%","%25"),"&","%26")," ","%20")) -> https://weddingditonike.vercel.app/?to=Monika%20Widiyana | D49: =Pengaturan!$B$4&CHAR(10)&CHAR(10)&"Kepada Yth."&CHAR(10)&"Bapak/Ibu/Saudara/i"&CHAR(10)&"*"&TRIM(A49)&"*"&CHAR(10)&CHAR(10)&Pengaturan!$B$5&CHAR(10)&Pengaturan!$B$3&"?to="&SUBSTITUTE(SUBSTITUTE(SUBSTITUTE(TRIM(A49),"%","%25"),"&","%26")," ","%20")&CHAR(10)&CHAR(10)&Pengaturan!$B$6 -> Dengan hormat, Kepada Yth. Bapak/Ibu/Saudara/i *Monika Widiyana* Tanpa mengurangi rasa hormat, perkenankan kami mengundang Bapak/Ibu/Saudara/i untuk menghadiri acara pernikahan kami. Berikut link undangan untuk info lengkap acara: https://weddingditonike.vercel.app/?to=Monika%20Widiyana Merupakan suatu kebahagiaan bagi kami apabila Bapak/Ibu/Saudara/i berkenan hadir dan memberikan doa restu. Terima kasih. Kami yang berbahagia, Dito & Nike
...

Sheet Pengaturan
A1: PENGATURAN LINK & PESAN
A2: Pengaturan | B2: Isi (sel kuning boleh diubah) | C2: Keterangan
A3: Alamat website undangan | B3: https://weddingditonike.vercel.app/ | C3: Ganti dengan alamat undangan di Vercel. Semua link di sheet Tamu ikut berubah otomatis.
A4: Salam pembuka | B4: Dengan hormat, | C4: Boleh diganti, mis. Assalamu'alaikum Wr. Wb.
A5: Kalimat undangan | B5: Tanpa mengurangi rasa hormat, perkenankan kami mengundang Bapak/Ibu/Saudara/i untuk menghadiri acara pernikahan kami. Berikut link undangan untuk info lengkap acara:
A6: Penutup | B6: Merupakan suatu kebahagiaan bagi kami apabila Bapak/Ibu/Saudara/i berkenan hadir dan memberikan doa restu. Terima kasih. Kami yang berbahagia, Dito & Nike
A8: Catatan: nama tamu diambil dari kolom A sheet Tamu. Spasi diubah jadi %20 dan tanda & jadi %26 supaya link aman.
